<?xml version="1.0" ?>
<!-- =================================================================================== -->
<!-- |    This document was autogenerated by xacro from robot.urdf.xacro               | -->
<!-- |    EDITING THIS FILE BY HAND IS NOT RECOMMENDED                                 | -->
<!-- =================================================================================== -->
<robot name="robot_name">
  <material name="blue">
    <color rgba="0 0 0.8 1"/>
  </material>
  <material name="grey">
    <color rgba="0.9 0.95 0.95 1.0"/>
  </material>
  <material name="black">
    <color rgba="0 0 0 1"/>
  </material>
  <material name="green">
    <color rgba="0.0 0.8 0.0 1.0"/>
  </material>
  <!-- Root Link -->
  <link name="base_footprint">
    </link>
  <link name="base_link">
    </link>
  <joint name="base_foot_to_base_link" type="fixed">
    <parent link="base_link"/>
    <child link="base_footprint"/>
    <origin rpy="0.0 0.0 0.0" xyz="0.0 0.0 0.0"/>
  </joint>
  <link name="base">
    <visual>
      <origin rpy="0.0 0.0 0.0" xyz="0.0 0.0 0"/>
      <geometry>
        <mesh filename="package://robot_description/meshes/base.stl" scale="0.3 0.3 0.3"/>
      </geometry>
      <material name="grey"/>
    </visual>
    <collision>
      <geometry>
        <box size="0.228 0.1455 0.054"/>
      </geometry>
    </collision>
    <inertial>
      <mass value="15.0"/>
      <origin rpy="0 0 0" xyz="0 0 0"/>
      <inertia ixx="0.030107812499999997" ixy="0.0" ixz="0.0" iyy="0.068625" iyz="0.0" izz="0.09144281250000001"/>
    </inertial>
  </link>
  <link name="front_right_wheel">
    <visual>
      <origin rpy="0 0 0" xyz="0 0 0"/>
      <geometry>
        <!-- <mesh filename="package://robot_description/meshes/blue_tyre.stl" scale="${scale_stl}" /> -->
        <mesh filename="package://robot_description/meshes/blue_tyre.stl" scale="0.3 0.3 0.3"/>
      </geometry>
      <material name="black"/>
    </visual>
    <collision>
      <origin rpy="1.5708 0 0" xyz="0 0 0"/>
      <geometry>
        <cylinder length="0.03" radius="0.06"/>
        <!-- <mesh filename="package://robot_description/meshes/blue_tyre.stl" scale="${scale_stl}" /> -->
      </geometry>
    </collision>
    <inertial>
      <mass value="1.0"/>
      <origin rpy="0 0 0" xyz="0 0 0"/>
      <inertia ixx="0.0009749999999999998" ixy="0" ixz="0" iyy="0.0018" iyz="0" izz="0.0009749999999999998"/>
    </inertial>
  </link>
  <gazebo reference="front_right_wheel">
    <material>Gazebo/Black</material>
    <mu1 value="0.8"/>
    <mu2 value="0.65"/>
  </gazebo>
  <link name="front_left_wheel">
    <visual>
      <origin rpy="0 0 0" xyz="0 0 0"/>
      <geometry>
        <!-- <mesh filename="package://robot_description/meshes/blue_tyre.stl" scale="${scale_stl}" /> -->
        <mesh filename="package://robot_description/meshes/blue_tyre.stl" scale="0.3 0.3 0.3"/>
      </geometry>
      <material name="black"/>
    </visual>
    <collision>
      <origin rpy="1.5708 0 0" xyz="0 0 0"/>
      <geometry>
        <cylinder length="0.03" radius="0.06"/>
        <!-- <mesh filename="package://robot_description/meshes/blue_tyre.stl" scale="${scale_stl}" /> -->
      </geometry>
    </collision>
    <inertial>
      <mass value="1.0"/>
      <origin rpy="0 0 0" xyz="0 0 0"/>
      <inertia ixx="0.0009749999999999998" ixy="0" ixz="0" iyy="0.0018" iyz="0" izz="0.0009749999999999998"/>
    </inertial>
  </link>
  <gazebo reference="front_left_wheel">
    <material>Gazebo/Black</material>
    <mu1 value="0.8"/>
    <mu2 value="0.65"/>
  </gazebo>
  <link name="rear_right_wheel">
    <visual>
      <origin rpy="0 0 0" xyz="0 0 0"/>
      <geometry>
        <!-- <mesh filename="package://robot_description/meshes/blue_tyre.stl" scale="${scale_stl}" /> -->
        <mesh filename="package://robot_description/meshes/blue_tyre.stl" scale="0.3 0.3 0.3"/>
      </geometry>
      <material name="black"/>
    </visual>
    <collision>
      <origin rpy="1.5708 0 0" xyz="0 0 0"/>
      <geometry>
        <cylinder length="0.03" radius="0.06"/>
        <!-- <mesh filename="package://robot_description/meshes/blue_tyre.stl" scale="${scale_stl}" /> -->
      </geometry>
    </collision>
    <inertial>
      <mass value="1.0"/>
      <origin rpy="0 0 0" xyz="0 0 0"/>
      <inertia ixx="0.0009749999999999998" ixy="0" ixz="0" iyy="0.0018" iyz="0" izz="0.0009749999999999998"/>
    </inertial>
  </link>
  <gazebo reference="rear_right_wheel">
    <material>Gazebo/Black</material>
    <mu1 value="0.8"/>
    <mu2 value="0.65"/>
  </gazebo>
  <link name="rear_left_wheel">
    <visual>
      <origin rpy="0 0 0" xyz="0 0 0"/>
      <geometry>
        <!-- <mesh filename="package://robot_description/meshes/blue_tyre.stl" scale="${scale_stl}" /> -->
        <mesh filename="package://robot_description/meshes/blue_tyre.stl" scale="0.3 0.3 0.3"/>
      </geometry>
      <material name="black"/>
    </visual>
    <collision>
      <origin rpy="1.5708 0 0" xyz="0 0 0"/>
      <geometry>
        <cylinder length="0.03" radius="0.06"/>
        <!-- <mesh filename="package://robot_description/meshes/blue_tyre.stl" scale="${scale_stl}" /> -->
      </geometry>
    </collision>
    <inertial>
      <mass value="1.0"/>
      <origin rpy="0 0 0" xyz="0 0 0"/>
      <inertia ixx="0.0009749999999999998" ixy="0" ixz="0" iyy="0.0018" iyz="0" izz="0.0009749999999999998"/>
    </inertial>
  </link>
  <gazebo reference="rear_left_wheel">
    <material>Gazebo/Black</material>
    <mu1 value="0.8"/>
    <mu2 value="0.65"/>
  </gazebo>
  <!-- Joints remain the same -->
  <joint name="base_link_to_base" type="fixed">
    <parent link="base_link"/>
    <child link="base"/>
    <origin rpy="0.0 0.0 0.0" xyz="0.0 0.0 0.06"/>
  </joint>
  <joint name="front_right_wheel_joint" type="continuous">
    <origin rpy="0 0 0" xyz="0.063 -0.105 0"/>
    <parent link="base"/>
    <child link="front_right_wheel"/>
    <axis xyz="0 1 0"/>
  </joint>
  <joint name="front_left_wheel_joint" type="continuous">
    <origin rpy="0 0 3.1415926" xyz="0.063 0.105 0"/>
    <parent link="base"/>
    <child link="front_left_wheel"/>
    <axis xyz="0 -1 0"/>
  </joint>
  <joint name="rear_right_wheel_joint" type="continuous">
    <origin rpy="0 0 0" xyz="-0.063 -0.105 0"/>
    <parent link="base"/>
    <child link="rear_right_wheel"/>
    <axis xyz="0 1 0"/>
  </joint>
  <joint name="rear_left_wheel_joint" type="continuous">
    <origin rpy="0 0 -3.1415926" xyz="-0.063 0.105 0"/>
    <parent link="base"/>
    <child link="rear_left_wheel"/>
    <axis xyz="0 -1 0"/>
  </joint>
  <joint name="depth_camera_joint" type="fixed">
    <parent link="base"/>
    <child link="depth_camera_link"/>
    <origin rpy="0 0 0" xyz="0.109 0 0.072"/>
  </joint>
  <link name="depth_camera_link">
    <visual>
      <geometry>
        <box size="0.010 0.03 0.03"/>
      </geometry>
      <material name="red"/>
    </visual>
  </link>
  <joint name="depth_camera_optical_joint" type="fixed">
    <parent link="depth_camera_link"/>
    <child link="depth_camera_link_optical"/>
    <origin rpy="-1.5707963267948966 0 -1.5707963267948966" xyz="0 0 0"/>
  </joint>
  <link name="depth_camera_link_optical"/>
  <gazebo reference="depth_camera_link">
    <material>Gazebo/Red</material>
    <sensor name="depth_camera" type="depth_camera">
      <pose> 0 0 0 0 0 0 </pose>
      <visualize>true</visualize>
      <update_rate>10</update_rate>
      <camera>
        <camera_info_topic>depth_camera/camera_info</camera_info_topic>
        <horizontal_fov>1.089</horizontal_fov>
        <image>
          <format>R_FLOAT32</format>
          <width>640</width>
          <height>480</height>
        </image>
        <clip>
          <near>0.05</near>
          <far>8.0</far>
        </clip>
      </camera>
      <depth_camera>
        <output>depths</output>
      </depth_camera>
      <topic>depth_camera/depth</topic>
      <gz_frame_id>depth_camera_link_optical</gz_frame_id>
    </sensor>
  </gazebo>
  <joint name="camera_joint" type="fixed">
    <parent link="base"/>
    <child link="camera_link"/>
    <origin rpy="0 0 0" xyz="0.109 0 0.075"/>
  </joint>
  <link name="camera_link">
    <visual>
      <geometry>
        <box size="0.010 0.03 0.03"/>
      </geometry>
      <material name="red"/>
    </visual>
  </link>
  <joint name="camera_optical_joint" type="fixed">
    <parent link="camera_link"/>
    <child link="camera_link_optical"/>
    <origin rpy="-1.5707963267948966 0 -1.5707963267948966" xyz="0 0 0"/>
  </joint>
  <link name="camera_link_optical"/>
  <gazebo reference="camera_link">
    <material>Gazebo/Red</material>
    <sensor name="camera" type="camera">
      <pose> 0 0 0 0 0 0 </pose>
      <visualize>true</visualize>
      <update_rate>10</update_rate>
      <camera>
        <camera_info_topic>camera/camera_info</camera_info_topic>
        <horizontal_fov>1.089</horizontal_fov>
        <image>
          <format>B8G8R8</format>
          <width>640</width>
          <height>480</height>
        </image>
        <clip>
          <near>0.05</near>
          <far>8.0</far>
        </clip>
      </camera>
      <topic>camera/image_raw</topic>
      <gz_frame_id>camera_link_optical</gz_frame_id>
    </sensor>
  </gazebo>
  <!-- adapted from https://github.com/joshnewans/articubot_one/blob/new_gazebo/description/gazebo_control.xacro -->
  <gazebo>
    <plugin filename="gz-sim-diff-drive-system" name="gz::sim::systems::DiffDrive">
      <!-- Wheel Information -->
      <left_joint>front_left_wheel_joint</left_joint>
      <left_joint>rear_left_wheel_joint</left_joint>
      <right_joint>front_right_wheel_joint</right_joint>
      <right_joint>rear_right_wheel_joint</right_joint>
      <wheel_separation>0.297</wheel_separation>
      <wheel_radius>0.033</wheel_radius>
      <!-- Limits -->
      <!-- <max_wheel_torque>200</max_wheel_torque> -->
      <max_linear_acceleration>0.33</max_linear_acceleration>
      <!-- Input -->
      <topic>cmd_vel</topic>
      <!-- Output -->
      <frame_id>odom</frame_id>
      <child_frame_id>base_link</child_frame_id>
      <odom_topic>odom</odom_topic>
      <odom_publisher_frequency>30</odom_publisher_frequency>
      <tf_topic>/tf</tf_topic>
    </plugin>
    <plugin filename="gz-sim-joint-state-publisher-system" name="gz::sim::systems::JointStatePublisher">
      <topic>joint_states</topic>
      <joint_name>front_left_wheel_joint</joint_name>
      <joint_name>rear_left_wheel_joint</joint_name>
      <joint_name>front_right_wheel_joint</joint_name>
      <joint_name>rear_right_wheel_joint</joint_name>
    </plugin>
  </gazebo>
  <!-- <xacro:include filename="imu.urdf.xacro" /> -->
  <!-- <xacro:imu /> -->
</robot>
